Workbook

Sheet Component list
A1: RoboCore V2 robot: component list
A2: Everything needed to build the robots with the arm, as of 2026-10-11. Prices are estimates in USD. Blue text = input you can change; yellow = fill in when you buy; green = from the Printed parts sheet.
B4: Robots to build | C4: 2
B5: Import VAT + duty allowance | C5: 0.16
A7: # | B7: Part | C7: What to buy / search for | D7: Per robot | E7: Unit | F7: For all robots | G7: Extra (spares / one-off) | H7: Total needed | I7: Pack size | J7: Packs to buy | K7: Est. price per pack (USD) | L7: Est. cost (USD) | M7: Where to buy | N7: Origin | O7: Actual paid (USD) | P7: Status | Q7: Check before buying / notes
A8: Controller board (on order at PCBWay)
A9: 1 | B9: RoboCore V2 controller, assembled | C9: PCBWay PCB W836287AS1F11 + assembly T-1F12W836287A: 2 assembled boards (+3 bare PCBs) | D9: 1 | E9: pcs | F9: =D9*$C$4 | G9: 0 | H9: =F9+G9 | I9: 2 | J9: =IF(H9=0,0,ROUNDUP(H9/I9,0)) | K9: 294.71 | L9: =IF(P9="Have already",0,J9*K9) | M9: PCBWay (quoted) | N9: Import | P9: Quoted | Q9: Quoted, not paid (awaiting audit): $57.43 PCB + $88 assembly + $144.40 parts + $34.88 FedEx − $30 coupon. Price is for the whole order of 2.
A10: Motors, sensors and servos
A11: 2 | B11: Motor pair with encoders (XRP motor) | C11: SparkFun ROB-24053: 2 motors, 1:48 gearbox, 585 counts per wheel turn, two 6-pin cables included | D11: 1 | E11: pair | F11: =D11*$C$4 | G11: 0 | H11: =F11+G11 | I11: 1 | J11: =IF(H11=0,0,ROUNDUP(H11/I11,0)) | K11: 28.5 | L11: =IF(P11="Have already",0,J11*K11) | M11: SparkFun (or a regional XRP reseller) | N11: Import | P11: To buy | Q11: The chassis motor pockets and encoder cover are built around this motor; a generic TT encoder motor won't fit. SparkFun showed 'Backorder' on 2026-10-11: check stock first. Wheels are printed.
A12: 3 | B12: Ultrasonic sensor, 3.3 V type | C12: Search: 'HC-SR04P' (3–5.5 V) or 'RCWL-1601'. 45 × 20 mm, Ø16 mm cans 26 mm apart | D12: 1 | E12: pcs | F12: =D12*$C$4 | G12: 1 | H12: =F12+G12 | I12: 1 | J12: =IF(H12=0,0,ROUNDUP(H12/I12,0)) | K12: 1.5 | L12: =IF(P12="Have already",0,J12*K12) | M12: AliExpress | N12: Import | P12: To buy | Q12: J403 supplies 3.3 V; the classic 5 V HC-SR04 is unreliable at 3.3 V. The pod is sized for the 45 × 20 mm board.
A13: 4 | B13: Line sensor, 3-channel | C13: Search: '3 channel TCRT5000 line tracking module analog'. Pins VCC GND L C R, about 60 × 24 mm | D13: 1 | E13: pcs | F13: =D13*$C$4 | G13: 1 | H13: =F13+G13 | I13: 1 | J13: =IF(H13=0,0,ROUNDUP(H13/I13,0)) | K13: 2.5 | L13: =IF(P13="Have already",0,J13*K13) | M13: AliExpress | N13: Import | P13: To buy | Q13: Must have ANALOG outputs (J404 is wired for analog); many modules are digital-only (LM339). The sled is sized for 60 × 24 mm: buy one first and check it fits. Dupont wires, so any pin order works.
A14: 5 | B14: Micro servo, metal gear (shoulder) | C14: MG90S, with horns and screws | D14: 1 | E14: pcs | F14: =D14*$C$4 | G14: 1 | H14: =F14+G14 | I14: 1 | J14: =IF(H14=0,0,ROUNDUP(H14/I14,0)) | K14: 3.5 | L14: =IF(P14="Have already",0,J14*K14) | M14: AliExpress | N14: Import | P14: To buy | Q14: Clone quality varies: buy from a well-reviewed store and test on arrival. Plugs straight into SERVO 1.
A15: 6 | B15: Micro servo (gripper) | C15: SG90, with horns and screws | D15: 1 | E15: pcs | F15: =D15*$C$4 | G15: 1 | H15: =F15+G15 | I15: 1 | J15: =IF(H15=0,0,ROUNDUP(H15/I15,0)) | K15: 2.5 | L15: =IF(P15="Have already",0,J15*K15) | M15: AliExpress | N15: Import | P15: To buy | Q15: Plugs into SERVO 2.
A16: Battery and power
A17: 7 | B17: 18650 Li-ion cell | C17: Branded (Samsung, LG, Molicel, EVE…), about 3000 mAh, 65 mm long, all the same type | D17: 3 | E17: pcs | F17: =D17*$C$4 | G17: 0 | H17: =F17+G17 | I17: 1 | J17: =IF(H17=0,0,ROUNDUP(H17/I17,0)) | K17: 3.5 | L17: =IF(P17="Have already",0,J17*K17) | M17: Local / South Africa | N17: Local | P17: To buy | Q17: Don't ship from China: couriers refuse loose cells and fakes are common. Match the cells (same type, same voltage) before fitting. Protected cells are ~70 mm long and may not fit the holder.
A18: 8 | B18: 3 × 18650 battery holder, parallel | C18: 61.6 × 78.4 mm, like the BatteryHolder3S in the model | D18: 1 | E18: pcs | F18: =D18*$C$4 | G18: 0 | H18: =F18+G18 | I18: 1 | J18: =IF(H18=0,0,ROUNDUP(H18/I18,0)) | K18: 2 | L18: =IF(P18="Have already",0,J18*K18) | M18: AliExpress | N18: Import | P18: To buy | Q18: Wire it 1S3P (all cells in parallel). A holder sold as '3S' is wired in series and must be rewired: the board takes 4.2 V maximum. The chassis V-rails are sized for 61.6 × 78.4 mm.
A19: 9 | B19: 1S Li-ion protection board (BMS) | C19: Search: '1S 3.7V 18650 protection board 5A' (DW01 type) | D19: 1 | E19: pcs | F19: =D19*$C$4 | G19: 1 | H19: =F19+G19 | I19: 5 | J19: =IF(H19=0,0,ROUNDUP(H19/I19,0)) | K19: 2 | L19: =IF(P19="Have already",0,J19*K19) | M19: AliExpress | N19: Import | P19: To buy | Q19: Recommended: the controller has no low-battery cut-off, so this stops the cells being over-drained. Goes between the holder and the XT30 lead. Pick one rated 5 A or more.
A20: 10 | B20: XT30 battery lead, female | C20: AMASS XT30U-F with 10–15 cm of 16 AWG silicone wire | D20: 1 | E20: pcs | F20: =D20*$C$4 | G20: 1 | H20: =F20+G20 | I20: 5 | J20: =IF(H20=0,0,ROUNDUP(H20/I20,0)) | K20: 4 | L20: =IF(P20="Have already",0,J20*K20) | M20: AliExpress (AMASS store) | N20: Import | P20: To buy | Q20: The board has the male XT30 (XT30UPB-M), so the battery side needs the female plug.
A21: 11 | B21: Heat-shrink tubing assortment | C21: For the battery wiring joints | D21: 0 | E21: set | F21: =D21*$C$4 | G21: 1 | H21: =F21+G21 | I21: 1 | J21: =IF(H21=0,0,ROUNDUP(H21/I21,0)) | K21: 2 | L21: =IF(P21="Have already",0,J21*K21) | M21: AliExpress / local | N21: Import | P21: To buy | Q21: One-off. Skip if you have some.
A22: Cables
A23: 12 | B23: Dupont jumper wires, female-female, 20 cm | C23: 4 for the ultrasonic (J403) + 5 for the line sensor (J404) | D23: 9 | E23: pcs | F23: =D23*$C$4 | G23: 0 | H23: =F23+G23 | I23: 40 | J23: =IF(H23=0,0,ROUNDUP(H23/I23,0)) | K23: 2 | L23: =IF(P23="Have already",0,J23*K23) | M23: AliExpress | N23: Import | P23: To buy | Q23: Usually sold as a 40-wire strip.
A24: 13 | B24: USB-C cable (data) | C24: USB-A or USB-C to USB-C; must carry data | D24: 1 | E24: pcs | F24: =D24*$C$4 | G24: 0 | H24: =F24+G24 | I24: 1 | J24: =IF(H24=0,0,ROUNDUP(H24/I24,0)) | K24: 2 | L24: =IF(P24="Have already",0,J24*K24) | M24: AliExpress / local | N24: Import | P24: To buy | Q24: For programming and charging. Charge-only cables won't program the board.
A25: 14 | B25: USB charger, 5 V 2 A (optional) | C25: Any phone charger with a USB-C or USB-A port | D25: 0 | E25: pcs | F25: =D25*$C$4 | G25: 0 | H25: =F25+G25 | I25: 1 | J25: =IF(H25=0,0,ROUNDUP(H25/I25,0)) | K25: 4 | L25: =IF(P25="Have already",0,J25*K25) | M25: Local | N25: Local | P25: To buy | Q25: Set 'Per robot' to 1 if the users don't have one. The board draws up to 1.65 A from USB.
A26: Screws, inserts and small hardware (with the arm and one bus clip)
A27: 15 | B27: M2 heat-set insert | C27: For Ø3.2 mm holes (e.g. M2 × 3 × 3.2 OD) | D27: 4 | E27: pcs | F27: =D27*$C$4 | G27: 4 | H27: =F27+G27 | I27: 100 | J27: =IF(H27=0,0,ROUNDUP(H27/I27,0)) | K27: 2 | L27: =IF(P27="Have already",0,J27*K27) | M27: AliExpress | N27: Import | P27: To buy | Q27: Board onto the deck.
A28: 16 | B28: M3 heat-set insert, short | C28: For Ø4.0 mm holes (e.g. M3 × 4 × 4.0 OD) | D28: 6 | E28: pcs | F28: =D28*$C$4 | G28: 4 | H28: =F28+G28 | I28: 100 | J28: =IF(H28=0,0,ROUNDUP(H28/I28,0)) | K28: 2.5 | L28: =IF(P28="Have already",0,J28*K28) | M28: AliExpress | N28: Import | P28: To buy | Q28: 2 dock towers, 3 clips (bus + 2 ballast), 1 bus-clip accessory boss.
A29: 17 | B29: M2 × 6 pan head machine screw | C29: Into the M2 inserts | D29: 4 | E29: pcs | F29: =D29*$C$4 | G29: 4 | H29: =F29+G29 | I29: 50 | J29: =IF(H29=0,0,ROUNDUP(H29/I29,0)) | K29: 1.5 | L29: =IF(P29="Have already",0,J29*K29) | M29: AliExpress | N29: Import | P29: To buy | Q29: Board onto the deck. Tip: one M2/M3 screw assortment kit covers most of this section.
A30: 18 | B30: M2 × 6 pan head self-tapping screw | C30: Wheel onto the motor shaft | D30: 2 | E30: pcs | F30: =D30*$C$4 | G30: 2 | H30: =F30+G30 | I30: 50 | J30: =IF(H30=0,0,ROUNDUP(H30/I30,0)) | K30: 1.5 | L30: =IF(P30="Have already",0,J30*K30) | M30: AliExpress | N30: Import | P30: To buy | Q30: Into the shaft's centre hole, with a washer.
A31: 19 | B31: M2 flat washer | D31: 2 | E31: pcs | F31: =D31*$C$4 | G31: 2 | H31: =F31+G31 | I31: 100 | J31: =IF(H31=0,0,ROUNDUP(H31/I31,0)) | K31: 1 | L31: =IF(P31="Have already",0,J31*K31) | M31: AliExpress | N31: Import | P31: To buy | Q31: Under the wheel screws.
A32: 20 | B32: M2 × 8 pan head screw | D32: 1 | E32: pcs | F32: =D32*$C$4 | G32: 1 | H32: =F32+G32 | I32: 50 | J32: =IF(H32=0,0,ROUNDUP(H32/I32,0)) | K32: 1.5 | L32: =IF(P32="Have already",0,J32*K32) | M32: AliExpress | N32: Import | P32: To buy | Q32: Shoulder horn centre screw (the servo's own screw is too short).
A33: 21 | B33: M2 × 5 pan head screw | D33: 2 | E33: pcs | F33: =D33*$C$4 | G33: 2 | H33: =F33+G33 | I33: 50 | J33: =IF(H33=0,0,ROUNDUP(H33/I33,0)) | K33: 1.5 | L33: =IF(P33="Have already",0,J33*K33) | M33: AliExpress | N33: Import | P33: To buy | Q33: Shoulder horn arm to the boom plate.
A34: 22 | B34: M2 × 4 pan head screw | D34: 3 | E34: pcs | F34: =D34*$C$4 | G34: 2 | H34: =F34+G34 | I34: 50 | J34: =IF(H34=0,0,ROUNDUP(H34/I34,0)) | K34: 1.5 | L34: =IF(P34="Have already",0,J34*K34) | M34: AliExpress | N34: Import | P34: To buy | Q34: Gripper horn: centre screw + 2 into the jaw.
A35: 23 | B35: M3 × 10 socket head screw | D35: 2 | E35: pcs | F35: =D35*$C$4 | G35: 2 | H35: =F35+G35 | I35: 50 | J35: =IF(H35=0,0,ROUNDUP(H35/I35,0)) | K35: 1.5 | L35: =IF(P35="Have already",0,J35*K35) | M35: AliExpress | N35: Import | P35: To buy | Q35: Sonar bracket + arm base into the dock (M3 × 8 if no arm).
A36: 24 | B36: M3 × 8 pan head self-tapping screw | D36: 1 | E36: pcs | F36: =D36*$C$4 | G36: 1 | H36: =F36+G36 | I36: 50 | J36: =IF(H36=0,0,ROUNDUP(H36/I36,0)) | K36: 1.5 | L36: =IF(P36="Have already",0,J36*K36) | M36: AliExpress | N36: Import | P36: To buy | Q36: Idle jaw pivot.
A37: 25 | B37: M3 × 8 thumb screw (knurled head) | D37: 3 | E37: pcs | F37: =D37*$C$4 | G37: 1 | H37: =F37+G37 | I37: 20 | J37: =IF(H37=0,0,ROUNDUP(H37/I37,0)) | K37: 3 | L37: =IF(P37="Have already",0,J37*K37) | M37: AliExpress | N37: Import | P37: To buy | Q37: Bus clip + 2 ballast clips (presses on the deck).
A38: 26 | B38: M8 hex nut | C38: Plain steel, about 5 g each | D38: 6 | E38: pcs | F38: =D38*$C$4 | G38: 0 | H38: =F38+G38 | I38: 1 | J38: =IF(H38=0,0,ROUNDUP(H38/I38,0)) | K38: 0.1 | L38: =IF(P38="Have already",0,J38*K38) | M38: Local hardware shop | N38: Local | P38: To buy | Q38: Ballast: 3 in each ballast clip. Needed when the arm is fitted.
A39: 27 | B39: ½" (12.7 mm) steel ball | C39: Bearing balls or slingshot ammo; 12.7 mm glass marbles also work | D39: 2 | E39: pcs | F39: =D39*$C$4 | G39: 2 | H39: =F39+G39 | I39: 20 | J39: =IF(H39=0,0,ROUNDUP(H39/I39,0)) | K39: 3 | L39: =IF(P39="Have already",0,J39*K39) | M39: AliExpress / local bearing shop | N39: Import | P39: To buy | Q39: Rear casters, press-fit.
A40: 3D printing filament (grams, from the Printed parts sheet)
A41: 28 | B41: PETG filament, yellow | C41: 1 kg spool | D41: ='Printed parts'!C24 | E41: g | F41: =D41*$C$4 | G41: ='Printed parts'!D24 | H41: =F41+G41 | I41: 1000 | J41: =IF(H41=0,0,ROUNDUP(H41/I41,0)) | K41: 20 | L41: =IF(P41="Have already",0,J41*K41) | M41: Local / Bambu store | N41: Local | P41: To buy | Q41: Chassis, sonar pod, arm and arm base.
A42: 29 | B42: PETG filament, black | C42: 1 kg spool | D42: ='Printed parts'!C25 | E42: g | F42: =D42*$C$4 | G42: ='Printed parts'!D25 | H42: =F42+G42 | I42: 1000 | J42: =IF(H42=0,0,ROUNDUP(H42/I42,0)) | K42: 20 | L42: =IF(P42="Have already",0,J42*K42) | M42: Local / Bambu store | N42: Local | P42: To buy | Q42: Line sled, jaws, clips, test pieces. Mark 'Have already' if you have black.
...

Sheet Printed parts
A1: RoboCore V2: 3D-printed parts and filament
A2: Masses from the shell/infill model in fusion/checks.py (mech/robot/README.md, rev 5). Files: mech/robot/print/, already in print orientation.
A3: Robots to build | C3: ='Component list'!C4
A4: Waste allowance (brim, purge, failed prints) | C4: 0.15
A6: Part | B6: Print file | C6: Per robot | D6: One-off (test pieces) | E6: Material | F6: Colour | G6: Mass each (g) | H6: Per robot (g) | I6: One-off (g) | J6: All robots (g) | K6: Notes
A7: Chassis | B7: RoboCore_V2_Chassis.3mf | C7: 1 | D7: 0 | E7: PETG | F7: Yellow | G7: 133 | H7: =C7*G7 | I7: =D7*G7 | J7: =H7*$C$3+I7 | K7: Deck (top) down. About 9–11 h on an A1 mini. Brim 5 mm if the corners lift
A8: Line sled | B8: RoboCore_V2_Line_sled_10.5.3mf | C8: 1 | D8: 0 | E8: PETG | F8: Black | G8: 3.6 | H8: =C8*G8 | I8: =D8*G8 | J8: =H8*$C$3+I8 | K8: 9.5 / 11.5 mm versions to taste. Sized for a 60 × 24 mm sensor board
A9: Wheel | B9: RoboCore_V2_Wheel.3mf | C9: 2 | D9: 0 | E9: PETG | F9: Dark teal | G9: 7.9 | H9: =C9*G9 | I9: =D9*G9 | J9: =H9*$C$3+I9 | K9: 30 % infill. Can be printed black to skip buying a teal spool
A10: Tyre | B10: RoboCore_V2_Tyre_TPU.3mf | C10: 2 | D10: 0 | E10: TPU 95A | F10: Black | G10: 4.6 | H10: =C10*G10 | I10: =D10*G10 | J10: =H10*$C$3+I10 | K10: Print slowly (25 mm/s or less)
A11: Sonar bracket (pod) | B11: RoboCore_V2_Sonar_bracket.3mf | C11: 1 | D11: 0 | E11: PETG | F11: Yellow | G11: 9 | H11: =C11*G11 | I11: =D11*G11 | J11: =H11*$C$3+I11 | K11: Plate top face down, pod up
A12: Arm base | B12: RoboCore_V2_Arm_base.3mf | C12: 1 | D12: 0 | E12: PETG | F12: Yellow | G12: 7.9 | H12: =C12*G12 | I12: =D12*G12 | J12: =H12*$C$3+I12 | K12: Arm module
A13: Arm | B13: RoboCore_V2_Arm.3mf | C13: 1 | D13: 0 | E13: PETG | F13: Yellow | G13: 11.1 | H13: =C13*G13 | I13: =D13*G13 | J13: =H13*$C$3+I13 | K13: Arm module, 30 % infill
A14: Jaw L (driven) | B14: RoboCore_V2_Jaw_L_driven.3mf | C14: 1 | D14: 0 | E14: PETG | F14: Black | G14: 1.1 | H14: =C14*G14 | I14: =D14*G14 | J14: =H14*$C$3+I14 | K14: 40 % infill
A15: Jaw R (idle) | B15: RoboCore_V2_Jaw_R_idle.3mf | C15: 1 | D15: 0 | E15: PETG | F15: Black | G15: 1.3 | H15: =C15*G15 | I15: =D15*G15 | J15: =H15*$C$3+I15 | K15: 40 % infill
A16: Ballast clip | B16: RoboCore_V2_Ballast_clip.3mf | C16: 2 | D16: 0 | E16: PETG | F16: Black | G16: 3.8 | H16: =C16*G16 | I16: =D16*G16 | J16: =H16*$C$3+I16 | K16: Needed with the arm (3 × M8 nuts each)
A17: Bus clip | B17: RoboCore_V2_Bus_clip.3mf | C17: 1 | D17: 1 | E17: PETG | F17: Black | G17: 1.7 | H17: =C17*G17 | I17: =D17*G17 | J17: =H17*$C$3+I17 | K17: Accessory clip; one extra printed first to test tolerances
A18: Rail coupon (test piece) | B18: RoboCore_V2_Rail_coupon.3mf | C18: 0 | D18: 1 | E18: PETG | F18: Black | G18: 3.3 | H18: =C18*G18 | I18: =D18*G18 | J18: =H18*$C$3+I18 | K18: Print once, first, to check your printer's tolerances
A20: Total per robot (g) | H20: =SUM(H7:H18) | I20: =SUM(I7:I18) | J20: =SUM(J7:J18)
A22: Filament to buy (includes the waste allowance)
A23: Material | B23: Colour | C23: Per robot (g) | D23: One-off (g) | E23: All robots (g)
A24: PETG | B24: Yellow | C24: =SUMIFS($H$7:$H$18,$E$7:$E$18,A24,$F$7:$F$18,B24)*(1+$C$4) | D24: =SUMIFS($I$7:$I$18,$E$7:$E$18,A24,$F$7:$F$18,B24)*(1+$C$4) | E24: =C24*$C$3+D24
A25: PETG | B25: Black | C25: =SUMIFS($H$7:$H$18,$E$7:$E$18,A25,$F$7:$F$18,B25)*(1+$C$4) | D25: =SUMIFS($I$7:$I$18,$E$7:$E$18,A25,$F$7:$F$18,B25)*(1+$C$4) | E25: =C25*$C$3+D25
A26: PETG | B26: Dark teal | C26: =SUMIFS($H$7:$H$18,$E$7:$E$18,A26,$F$7:$F$18,B26)*(1+$C$4) | D26: =SUMIFS($I$7:$I$18,$E$7:$E$18,A26,$F$7:$F$18,B26)*(1+$C$4) | E26: =C26*$C$3+D26
A27: TPU 95A | B27: Black | C27: =SUMIFS($H$7:$H$18,$E$7:$E$18,A27,$F$7:$F$18,B27)*(1+$C$4) | D27: =SUMIFS($I$7:$I$18,$E$7:$E$18,A27,$F$7:$F$18,B27)*(1+$C$4) | E27: =C27*$C$3+D27
A29: Print time: about 13 printer-hours per robot on an A1 mini (chassis 9–11 h). Estimate; slice to confirm.
A30: Settings: 0.2 mm layers, 3 walls, 25 % gyroid (wheels and arm 30 %, jaws and clips 40 %), no supports, PETG 240–250 °C.

Sheet Notes
A1: RoboCore V2 component list: notes
A4: How to use it
A5: Change 'Robots to build' (Component list, C4) and every quantity and total updates. The filament grams follow the Printed parts sheet.
A6: Blue text = inputs you can change (quantities, spares, pack sizes, estimated prices, origin, status).
A7: Lines marked 'Have already' count as $0 in the estimate (e.g. a filament colour you already have).
A8: Yellow cells = fill in the real price when you pay ('Actual paid', the total for that line). The summary adds them up.
A9: Green text = linked from the Printed parts sheet. Black = formulas; don't type over them.
A10: Status drop-down: To buy / Quoted / Ordered / Received / Have already. Use the filter arrows on the header row to see what is left.
A12: Check before buying
A13: 1. Motors: the chassis is built around the SparkFun XRP motor (ROB-24053). Generic TT encoder motors have a different encoder cover, plug (PH2.0) and pin order.
A14: 2. Ultrasonic: J403 gives 3.3 V, so buy a 3.3 V-capable module (HC-SR04P or RCWL-1601), not the classic 5 V HC-SR04.
A15: 3. Line sensor: needs analog outputs, and the printed sled is sized for a 60 × 24 mm board. Buy one first and check it.
... A27: Connector facts (J403 3.3 V, J404 analog, XT30 male on the board): docs/RoboCore_V2_spec.md.
